Workbook
Name range1: '(참고) ETRI 12대 전략기술 및 42개 세부기술'!$E$3:$E$11
Name range10: '(참고) ETRI 12대 전략기술 및 42개 세부기술'!$E$46:$E$48
Name range11: '(참고) ETRI 12대 전략기술 및 42개 세부기술'!$E$49:$E$51
Name range12: '(참고) ETRI 12대 전략기술 및 42개 세부기술'!$E$52:$E$56
Name range2: '(참고) ETRI 12대 전략기술 및 42개 세부기술'!$E$12:$E$14
Name range3: '(참고) ETRI 12대 전략기술 및 42개 세부기술'!$E$15:$E$17
Name range4: '(참고) ETRI 12대 전략기술 및 42개 세부기술'!$E$18:$E$19
Name range5: '(참고) ETRI 12대 전략기술 및 42개 세부기술'!$E$20:$E$24
Name range6: '(참고) ETRI 12대 전략기술 및 42개 세부기술'!$E$25:$E$30
Name range7: '(참고) ETRI 12대 전략기술 및 42개 세부기술'!$E$31:$E$36
Name range8: '(참고) ETRI 12대 전략기술 및 42개 세부기술'!$E$37:$E$41
Name range9: '(참고) ETRI 12대 전략기술 및 42개 세부기술'!$E$42:$E$45

Sheet 취합
A1: 소 | B1: 본부(단) | C1: 순번 | D1: 표준 제목 (예정) | E1: 표준번호 | F1: 표준기구 | G1: 위원회, 작업반 등 | H1: 표준화 상태 | I1: 표준 주요 내용 | J1: (예정) 시작년도 | K1: (예정) 완료연도 | L1: ETRI 기고자 | M1: ETRI 에디터(예정포함) | N1: ETRI 의장단 | O1: 사업분류 | P1: 출연처 | Q1: 전략기술 분야 | R1: 세부중점기술 분야 | S1: 표준특허 유무 | T1: 표준특허 개수 | U1: 특허상태(출원/등록) | V1: ETRI 관리번호 | W1: 표준특허명 | X1: 출원국가 | Y1: 1발명자 | AA1: 변경여부
A2: ICT전략연구소 | B2: 표준연구본부 | C2: 1 | D2: Framework for multicast-based IPTV content delivery | E2: ITU-T Y.1902 | F2: ITU-T | G2: SG13 Q3 | H2: 제정완료 | I2: 멀티캐스트 기반 IPTV 컨텐츠 전달을 위한 프레임웍 | J2: 2008 | K2: 2011 | L2: 강신각, 이승익 | O2: 표준개발과제(과기부 정보통신방송표준개발지원사업) | P2: 과기부 | Q2: 7) 차세대통신 | R2: 기타 | S2: 무 | T2: 0
A3: ICT전략연구소 | B3: 표준연구본부 | C3: 2 | D3: Guidelines on deployment of IP multicast for IPTV content delivery | E3: ITU-T Y Sup.16 | F3: ITU-T | G3: SG13 Q3 | H3: 제정완료 | I3: 멀티캐스트 기반 IPTV 컨텐츠 전달을 위한 설치 가이드라인 | J3: 2009 | K3: 2012 | L3: 강신각, 이승익 | O3: 표준개발과제(과기부 정보통신방송표준개발지원사업) | P3: 과기부 | Q3: 10) 메타버스 | R3: 기타 | S3: 무 | T3: 0
A4: ICT전략연구소 | B4: 표준연구본부 | C4: 3 | D4: Functional requirements of Mobile IPTV | E4: ITU-T Y.1903 | F4: ITU-T | G4: SG13 Q3 | H4: 제정완료 | I4: 모바일 IPTV 기능 요구사항 | J4: 2010 | K4: 2014 | L4: 강신각, 이승익 | O4: 표준개발과제(과기부 정보통신방송표준개발지원사업) | P4: 과기부 | Q4: 10) 메타버스 | R4: 기타 | S4: 무 | T4: 0
A5: ICT전략연구소 | B5: 표준연구본부 | C5: 4 | D5: Smart Ubiquitous Networks - Functional architecture of content delivery | E5: ITU-T Y.3045 | F5: ITU-T | G5: SG13 Q3 | H5: 제정완료 | I5: 스마트 유비쿼터스 네트워크 (SUN) 를 위한 컨텐츠 전달 기능 구조 | J5: 2012 | K5: 2014 | L5: 강신각, 이승익 | O5: 표준개발과제(과기부 정보통신방송표준개발지원사업) | P5: 과기부 | Q5: 12) ICT융합 | R5: 기타 | S5: 무 | T5: 0
A6: ICT전략연구소 | B6: 표준연구본부 | C6: 5 | D6: Web-based terminal middleware for IPTV services | E6: ITU-T H.730 | F6: ITU-T | G6: SG16 Q13 | H6: 제정완료 | I6: 본 표준은 IPTV 서비스에 필요한 웹 기반 단말 미들웨어, 일반 아키텍처 및 인터페이스를 정의 | J6: 2009 | K6: 2012 | L6: 김성한 | O6: 표준개발과제(과기부 정보통신방송표준개발지원사업) | P6: 과기부 | Q6: 10) 메타버스 | R6: 초실감 입체 미디어 기술 | S6: 무 | T6: 0
A7: ICT전략연구소 | B7: 표준연구본부 | C7: 6 | D7: Enhanced user interface framework for IPTV terminal devices | E7: ITU-T H.703 | F7: ITU-T | G7: SG16 Q13 | H7: 제정완료 | I7: 본 표준은 IPTV 단말 장치의 향상된 사용자 인터페이스를 지원하기 위한 프레임워크의 이벤트 특징, 일반 요구 사항 및 기능에 대해 설명 | J7: 2013 | K7: 2016 | L7: 김성한 | O7: 표준개발과제(과기부 정보통신방송표준개발지원사업) | P7: 과기부 | Q7: 10) 메타버스 | R7: 초실감 입체 미디어 기술 | S7: 무 | T7: 0
A8: ICT전략연구소 | B8: 표준연구본부 | C8: 7 | D8: Scene-based metadata for IPTV services | E8: ITU-T H.753 | F8: ITU-T | G8: SG16 Q13 | H8: 제정완료 | I8: 본 표준은 인터넷 프로토콜 텔레비전(IPTV) 서비스를 위한 장면 기반 메타데이터 제안. 콘텐츠 배포를 위한 장면 기반 메타데이터 설명, 메타데이터 요소 및 형식을 정의 | J8: 2016 | K8: 2019 | L8: 김성한 | O8: 표준개발과제(과기부 정보통신방송표준개발지원사업) | P8: 과기부 | Q8: 10) 메타버스 | R8: 초실감 입체 미디어 기술 | S8: 무 | T8: 0
A9: ICT전략연구소 | B9: 표준연구본부 | C9: 8 | D9: Gesture Interface Markup Language | E9: ISO/IEC 30113-5 | F9: ISO/IEC JTC1 | G9: SC35 | H9: 제정완료 | I9: 본 표준은 제스쳐 인터페이스를 위한 손 동작 모양의 인식을 위한 제스쳐 메타데이터 정의 | J9: 2016 | K9: 2019 | L9: 김성한 | O9: 표준개발과제(과기부 정보통신방송표준개발지원사업) | P9: 과기부 | Q9: 10) 메타버스 | R9: 초실감 상호작용 기술 | S9: 무 | T9: 0
A10: ICT전략연구소 | B10: 표준연구본부 | C10: 9 | D10: Enhanced user interface framework for IPTV terminal device - Gesture control interface | E10: ITU-T H.704 | F10: ITU-T | G10: SG16 Q13 | H10: 제정완료 | I10: 본 표준안은 권고안 ITU-T H.703에 정의된 향상된 사용자 인터페이스(UI) 프레임워크를 기반으로 제스처 인식 및 인터넷 프로토콜 TV(IPTV) 단말 장치 제어를 통한 사용자 상호작용의 향상된 기능을 지원하는 일반 요구사항, 기능 요소 및 인터페이스 정의 | J10: 2017 | K10: 2020 | L10: 김성한 | M10: 에디터(김성한) | O10: 표준개발과제(과기부 정보통신방송표준개발지원사업) | P10: 과기부 | Q10: 10) 메타버스 | R10: 초실감 입체 미디어 기술 | S10: 무 | T10: 0 | AA10: R
A11: ICT전략연구소 | B11: 표준연구본부 | C11: 10 | D11: Emotion enabled multimodal user interface based on artificial neural networks | E11: ITU-T H.862.5 | F11: ITU-T | G11: SG16 Q24 | H11: 제정완료 | I11: 본 표준은 인공 신경망에 기반한 감정 지원 멀티모달 사용자 인터페이스를 위한 기능 엔티티와 아키텍처 제공 | J11: 2019 | K11: 2021 | L11: 김성한 | M11: 에디터(김성한) | O11: 표준개발과제(과기부 정보통신방송표준개발지원사업) | P11: 과기부 | Q11: 10) 메타버스 | R11: 초실감 입체 미디어 기술 | S11: 무 | T11: 0
A12: ICT전략연구소 | B12: 표준연구본부 | C12: 11 | D12: Lightweight intelligent software framework for Internet of things devices | E12: ITU-T Y.4475 | F12: ITU-T | G12: SG20 Q4 | H12: 제정완료 | I12: 본 표준은 지능형 처리가 필요한 사물 인터넷(IoT) 애플리케이션을 지원하고 리소스가 제한된 IoT 장치에서 이러한 처리가 작동할 수 있도록 하는 경량 지능형 소프트웨어 프레임워크(LISF) 정의 | J12: 2019 | K12: 2021 | L12: 김성한 | M12: 에디터(김성한) | N12: SG20 의장(김형준) | O12: ETRI 출연금사업 | P12: 과기부 | Q12: 7) 차세대통신 | R12: 5G 고도화 | S12: 무 | T12: 0 | AA12: R
A13: ICT전략연구소 | B13: 표준연구본부 | C13: 12 | D13: Trusted contribution evaluation framework on federated machine learning services | E13: ITU-T F.748.24 | F13: ITU-T | G13: SG16 Q5 | H13: 제정완료 | I13: 본 표준은 연합 머신러닝 서비스에 대한 기여도 평가 서비스를 소개하고 개념, 특성, 요구 사항, 사용 사례를 제공하며 참조 프레임워크와 공통 기능을 명시 | J13: 2021 | K13: 2023 | L13: 김성한 | M13: 에디터(김성한) | N13: SG16 부의장(강신각) | O13: 일반 PBS 과제 | P13: 국방부 | Q13: 7) 차세대통신 | R13: 5G 고도화 | S13: 무 | T13: 0 | AA13: R
A14: ICT전략연구소 | B14: 표준연구본부 | C14: 13 | D14: Metadata for camera sensing information of autonomous mobile IoT devices | E14: ITU-T Y.4604 | F14: ITU-T | G14: SG20 Q4 | H14: 제정완료 | I14: 본 표준은 카메라 감지 정보(MCSI)에 대한 메타데이터를 정의하고 자율 모바일 IoT 디바이스(AMID)에서 작동하는 개별 MCSI의 특성과 기능을 정의 | J14: 2021 | K14: 2023 | L14: 김성한 | M14: 에디터(김성한) | N14: SG20 의장(김형준) | O14: 일반 PBS 과제 | P14: 과기부 | Q14: 3) 첨단모빌리티 | R14: 도심항공교통(UAM) | S14: 무 | T14: 0
A15: ICT전략연구소 | B15: 표준연구본부 | C15: 14 | D15: Information technology - Relayed multicast protocol: Specification for N-plex group applications | E15: ITU-T X.603.2 | F15: ITU-T | G15: SG11 Q15 | H15: 제정완료 | I15: IP 멀티캐스트가 지원하지 않는 인터넷에서 여러 발신자에서 여러 수신자로 데이터를 전달하는 N-plex 데이터 중계를 위한 기능 요구사항과 응용 계층 전달 프로토콜 정의 | J15: 2009 | K15: 2010 | L15: 김성혜 | M15: 에디터(김성혜) | N15: SG11 Q8 라포처(이창규), SG11 WP2 의장(강신각) | O15: 표준개발과제(과기부 정보통신방송표준개발지원사업) | P15: 과기부 | Q15: 7) 차세대통신 | R15: 기타 | S15: 무 | T15: 0
A16: ICT전략연구소 | B16: 표준연구본부 | C16: 15 | D16: Information technology - Mobile multicast communications: Protocol over overlay multicast networks | E16: ITU-T X.604.2 | F16: ITU-T | G16: SG11 Q15 | H16: 제정완료 | I16: IP 멀티캐스트가 지원하지 않는 인터넷에서 유무선 통합 네트워크 환경에서 일대다 데이터 중계를 위한 기능 요구사항 및 응용 계층 전달 프로토콜 정의 | J16: 2009 | K16: 2010 | L16: 김성혜 | M16: 에디터(김성혜) | N16: SG11 Q8 라포처(이창규), SG11 WP2 의장(강신각) | O16: 표준개발과제(과기부 정보통신방송표준개발지원사업) | P16: 과기부 | Q16: 7) 차세대통신 | R16: 기타 | S16: 무 | T16: 0
A17: ICT전략연구소 | B17: 표준연구본부 | C17: 16 | D17: Information technology — Telecommunications and information exchange between systems — Managed P2P: Framework | E17: ISO/IEC TR 20002 | F17: ISO/IEC JTC1 | G17: SC6 | H17: 제정완료 | I17: 일반 P2P 네트워킹의 문제점 정의, 관리형 P2P의 분류 및 개념을 정의, 관리형 P2P를 지원하기 위한 요구 사항 정의, 관리형 P2P 프레임워크 정의, 관리형 P2P 지원하기 위한 정보 흐름 정의 | J17: 2011 | K17: 2012 | L17: 김성혜 | M17: 에디터(김성혜) | O17: 표준개발과제(과기부 정보통신방송표준개발지원사업) | P17: 과기부 | Q17: 7) 차세대통신 | R17: 기타 | S17: 무 | T17: 0
A18: ICT전략연구소 | B18: 표준연구본부 | C18: 17 | D18: Information technology - Relayed multicast protocol: Specification for simplex group applications | E18: ITU-T X.603.1 | F18: ITU-T | G18: SG11 Q15 | H18: 제정완료 | I18: IP 멀티캐스트가 지원하지 않는 인터넷에서 일대다 데이터 중계를 위한 기능 요구사항과 응용 계층 전달 프로토콜 정의 | J18: 2011 | K18: 2012 | L18: 김성혜 | M18: 에디터(김성혜) | N18: SG11 Q8 라포처(이창규), SG11 WP2 의장(강신각) | O18: 표준개발과제(과기부 정보통신방송표준개발지원사업) | P18: 과기부 | Q18: 7) 차세대통신 | R18: 기타 | S18: 유 | T18: 3 | U18: 1.출원 2.등록 3.등록 | V18: 1.PR20090647 2.PR20100770 3.PR20120200 | W18: 1. 중계전송 오버레이 멀티캐스트 기능에서 안정된 멀티캐스트 트리 구성을 위한 세션 관리 방법 2. 오버레이 멀티캐스트 네트워크 기반 오버레이 멀티캐스트 서비스 제공 방법 및 그 장치 3. 중계전송 멀티캐스트 네트워크에서 멀티캐스트 에이전트에게 매개변수를 전송하는 방법 및 장치 | X18: 1. 한국 2. 미국 3. 미국 | Y18: 1. 김성혜 2. 김성혜 3. 김성혜
A19: ICT전략연구소 | B19: 표준연구본부 | C19: 18 | D19: Future Network: Problem Statement and Requirements – Part 6: Media Distribution | E19: ISO/IEC TR 29181-6 | F19: ISO/IEC JTC1 | G19: SC6 | H19: 제정완료 | I19: 현재 IP 기반 네트워크의 미디어 전송 문제를 식별하고 미래 네트워크를 통한 미디어 데이터 전송에 대한 요구 사항 정의 | J19: 2012 | K19: 2013 | L19: 김성혜 | M19: 에디터(김성혜) | N19: SC6 컨비너(강신각) | O19: 표준개발과제(과기부 정보통신방송표준개발지원사업) | P19: 과기부 | Q19: 7) 차세대통신 | R19: 기타 | S19: 무 | T19: 0
A20: ICT전략연구소 | B20: 표준연구본부 | C20: 19 | D20: W3C TV Control API Specification | F20: W3C | G20: TVControlAPI | H20: 제정완료 | I20: Smart TV, IPTV 등 인터넷에서 채널 및 프로그램 메타데이터를 사용하여 방송, IPTV 또는 기타 소스의 TV 및 라디오와 같은 오디오 및 비디오 미디어를 소싱하기 위한 API를 정의 | J20: 2014 | K20: 2016 | L20: 김성혜 | M20: 에디터(김성혜) | O20: 표준개발과제(과기부 정보통신방송표준개발지원사업) | P20: 과기부 | Q20: 12) ICT융합 | R20: 기타 | S20: 무 | T20: 0
A21: ICT전략연구소 | B21: 표준연구본부 | C21: 20 | D21: APT REPORT ON “SERVICES AND APPLICATIONS OF WIRELESS POWER TRANSMISSION TECHNOLOGY” | E21: APT/AWG/REP-71 | F21: APT | G21: AWG | H21: 제정완료 | I21: 무선 전력 전송(WPT) 기술을 적용한 장치 및 서비스 분석, 예상 인프라 분석 및 연구 항목 및 WPT 서비스 배포 시나리오 정의. | J21: 2016 | K21: 2017 | L21: 김성혜 | M21: 에디터(김성혜) | O21: 표준개발과제(과기부 정보통신방송표준개발지원사업) | P21: 과기부 | Q21: 12) ICT융합 | R21: 기타 | S21: 무 | T21: 0 | AA21: R
A22: ICT전략연구소 | B22: 표준연구본부 | C22: 21 | D22: Framework of wireless power transmission application service | E22: ITU-T Y.4202 | F22: ITU-T | G22: SG20 Q4 | H22: 제정완료 | I22: 무선 전력 전송(WPT)기반의 응용 서비스 개념, 기능 모델, 요구사항, 기본 서비스 흐름 및 서비스 유스케이스 정의 | J22: 2018 | K22: 2019 | L22: 김성혜, 박주영 | M22: 에디터(김성혜) | N22: SG20 의장(김형준) | O22: 표준개발과제(과기부 정보통신방송표준개발지원사업) | P22: 과기부 | Q22: 12) ICT융합 | R22: 기타 | S22: 유 | T22: 1 | U22: 1.출원 | V22: 1.PR20160134 | W22: 1. 무선 충전 장치, 무선 충전 단말 및 무선 충전 서비스 제공 방법 | X22: 1. 한국 | Y22: 1. 김성혜 | AA22: R
A23: ICT전략연구소 | B23: 표준연구본부 | C23: 22 | D23: Framework for access permission of Person-Generated Health Records in digital health | E23: ITU-T F.HR-AP | F23: ITU-T | G23: SG21 Q2 | H23: 개발중 | I23: 의료 기관 외부에서 수집된 PGHR을 보유하는 디지털 건강 플랫폼 내에서 개인 생성 건강 기록(PGHR)에 대한 액세스 권한을 부여하기 위한 지침과 프레임워크을 정의함표준에서는 PGHR 접근 권한과 관련하여 다양한 문제를 식별하고 안전하게 개인 건강 정보를 공유하는 프레임워크를 정의하고, 개인 건강 정보를 사용에 대한 가이드라인을 제시함 | J23: 2023 | K23: 2025 | L23: 김성혜, 선경재 | M23: 에디터(김성혜) | N23: SG21 부의장(강신각) | O23: 표준개발과제(과기부 정보통신방송표준개발지원사업) | P23: 과기부 | Q23: 4) 첨단바이오 | R23: 디지털헬스 데이터 분석·활용 | S23: 무 | T23: 0
A24: ICT전략연구소 | B24: 표준연구본부 | C24: 23 | D24: Dgital twin framework for manufacturing - Part 5: Digital thread for digital twin | E24: ISO/CD 23247-5 | F24: ISO | G24: TC184 SC4 WG15 | H24: 개발중 | I24: 디지털 트윈에서 디지털 스레드를 이용하기 위한 개념 및 방법론을 정의하고, 디지털 스레드를 사용 사례 예시를 제공함으로써 디지털 스레드가 제품 수명 주기 전반에 걸쳐 제조 디지털 트윈의 생성, 연결, 관리 및 유지 관리를 가능하게 하는 방법 정의함 | J24: 2023 | K24: 2026 | L24: 김성혜, 선경재, 유상근, 김용운, 손지연, 이학진 | M24: 프로젝트 리더(김성혜) | O24: 일반 PBS 과제 | P24: 과기부 | Q24: 8) 첨단로봇제조 | R24: 가상제조 | S24: 무 | T24: 0 | AA24: R
A25: ICT전략연구소 | B25: 표준연구본부 | C25: 24 | D25: Health informatics — Guideline for self-assessment questionnaire systems | E25: ISO/TS 9166 | F25: ISO | G25: TC 215 WG2 | H25: 제정완료 | I25: 자가진단 문진 시스템 개발을 위한 가이드라인으로 문진시스템 게발 요구사항, 문진을 위한 데이터 엘리먼트 등 정의 | J25: 2025 | K25: 2025 | L25: 김성혜, 유상근, 김용운, 이창규 | M25: 프로젝트 리더(김성혜) | O25: 표준개발과제(국표원 표준기술력향상사업) | P25: 산업부 | Q25: 12) ICT융합 | R25: 기타 | S25: 무 | T25: 0 | AA25: R
A26: ICT전략연구소 | B26: 표준연구본부 | C26: 25 | D26: Automation systems and integration — Digital twin framework for manufacturing — Part 4: Information exchange | E26: ISO 23247-4 | F26: ISO | G26: TC184 SC4 WG15 | H26: 제정완료 | I26: 제조 분야에 적용하기 위한 디지털 트윈 프레임워크 중 정보교환 요구사항, 절차 등을 정의 | J26: 2018 | K26: 2021 | L26: 김성혜, 유상근, 이현정, 이진영 | M26: 프로젝트 리더(김성혜) | O26: 표준개발과제(국표원 표준기술력향상사업) | P26: 산업부 | Q26: 8) 첨단로봇제조 | R26: 가상제조 | S26: 무 | T26: 0
A27: ICT전략연구소 | B27: 표준연구본부 | C27: 26 | D27: Digital signage: Metadata | E27: ITU-T H.782 | F27: ITU-T | G27: SG16 Q14 | H27: 제정완료 | I27: 디지털 사이니지 서비스에서 사용되는 메타데이터 요구사항과 메타데이터 구조를 정의함 | J27: 2016 | K27: 2017 | L27: 김성혜, 허미영 | M27: 에디터(김성혜) | O27: 표준개발과제(과기부 정보통신방송표준개발지원사업) | P27: 과기부 | Q27: 12) ICT융합 | R27: 기타 | S27: 무 | T27: 0
A28: ICT전략연구소 | B28: 표준연구본부 | C28: 27 | D28: Managed P2P communications: Overlay Resource Control Protocol (ORCP) | E28: ITU-T X.609.2 | F28: ITU-T | G28: SG11 Q9 | H28: 제정완료 | I28: ORCP(Overlay Resource Control Protocol)을 정의하며, 이는 캐시 서버(CS)/릴레이 서버(RS)와 오버레이 관리 서버(OMS) 사이의 인터페이스와 OMS와 피어 사이의 인터페이스에서 실행되는 오버레이 리소스 제어 프로토콜 정의 | J28: 2015 | K28: 2016 | L28: 김성혜, 현욱 | M28: 에디터(김성혜) | O28: 표준개발과제(과기부 정보통신방송표준개발지원사업) | P28: 과기부 | Q28: 7) 차세대통신 | R28: 기타 | S28: 유 | T28: 3 | U28: 1.등록 2.등록 3.등록 | V28: 1.PR20120779 2.PR20151075 3.PR20160222 | W28: 1. 피투피 네트워크에서 피어의 상태 정보를 관리하거나 공유하는 방법 및 장치 2. 네트워크 관리 서버의 자원 관리 방법 및 네트워크 관리 서버를 포함하는 피투피 시스템 3. 오버레이 관리 서버 및 이의 자원 할당 방법 | X28: 1. 한국 2. 미국 3. 미국 | Y28: 1. 김성혜 2. 김성혜 3. 김성혜
A29: ICT전략연구소 | B29: 표준연구본부 | C29: 28 | D29: Framework of delegation service for Internet of things devices | E29: Y.4463-rev | F29: ITU-T | G29: SG20 Q4 | H29: 제정완료 | I29: 물리/가상공간 간 센싱 데이터의 소유권 관리 모델표준 및 센싱데이터 저장 및 공유 기법 제시 | J29: 2023 | K29: 2024 | L29: 김영호, 박정수, 이윤경 | M29: 에디터(김영호) | N29: SG20 의장(김형준) | O29: 표준개발과제(과기부 정보통신방송표준개발지원사업) | P29: 과기부 | Q29: 5) 사이버보안 | R29: 네트워크 클라우드 보안 | S29: 유 | T29: 1 | Z29: 타부서실적
A30: ICT전략연구소 | B30: 표준연구본부 | C30: 29 | D30: NGN service requirements and capabilities for network aspects of applications and services using tag-based identification | E30: ITU-T Y.2213 | F30: ITU-T | G30: SG13 Q2 | H30: 제정완료 | I30: 바코드, RFID 등 식별용 태그를 활용하여 정보 서비스를 제공하는 네트워크, 응용, 및 서비스를 위한 요구사항 정의 | J30: 2004 | K30: 2008 | L30: 김용운 | M30: 에디터(김용운) | O30: 표준개발과제(과기부 정보통신방송표준개발지원사업) | P30: 과기부 | Q30: 12) ICT융합 | R30: 산업ICT융합 | S30: 무 | T30: 0 | AA30: R
A31: ICT전략연구소 | B31: 표준연구본부 | C31: 30 | D31: Testing and model network architecture for tag-based identification systems and functions | E31: ITU-T Q.3950 | F31: ITU-T | G31: SG11 Q12 | H31: 제정완료 | I31: 바코드, RFID 등 식별용 태그를 활용하여 정보 서비스를 제공하는 네트워크, 응용, 및 서비스 대상 적합성과 상호운용성 시험을 지원하는 기능 구조를 정의 | J31: 2008 | K31: 2011 | L31: 김용운 | M31: 에디터(김용운) | N31: SG11 Q12 라포처(김용운) | O31: 표준개발과제(과기부 정보통신방송표준개발지원사업) | P31: 과기부 | Q31: 12) ICT융합 | R31: 산업ICT융합 | S31: 무 | T31: 0
A32: ICT전략연구소 | B32: 표준연구본부 | C32: 31 | D32: Methodology for assessment of the environmental impact of information and communication technology greenhouse gas and energy projects | E32: ITU-T L.1430 | F32: ITU-T | G32: SG5 Q18 | H32: 제정완료 | I32: ICT 분야에서 온실가스 감축 또는 에너지 소비 절감 프로젝트를 진행할 때 감축 및 절감 계량화를 산정함으로써 환경 영향을 평가하는 방법을 설명 | J32: 2010 | K32: 2013 | L32: 김용운 | M32: 에디터(김용운) | N32: SG5 WP3 부의장(김용운) | O32: 표준개발과제(과기부 정보통신방송표준개발지원사업) | P32: 과기부 | Q32: 12) ICT융합 | R32: 에너지ICT융합 | S32: 무 | T32: 0
A33: ICT전략연구소 | B33: 표준연구본부 | C33: 32 | D33: Interface model and its requirements of integrating virtual and physical worlds through digital twins for the metaverse | E33: ITU-T Y.dtmv-if | F33: ITU-T | G33: SG20 Q1 | H33: 개발중 | I33: 디지털 트윈 기반의 현실 가상 통합을 통해 메타버스 서비스로서 제공할 때 기능 구성요소들과 외부 정보시스템 간의 데이터 인터페이스에 대한 모델과 관련 요구사항 정의 | J33: 2024 | K33: 2025 | L33: 김용운 | M33: 에디터(김용운) | N33: SG20 Q1 라포처(이준섭) SG20 의장(김형준) | O33: 표준개발과제(과기부 정보통신방송표준개발지원사업) | P33: 과기부 | Q33: 10) 메타버스 | R33: 초실감 상호작용 기술 | S33: 유 | T33: 1 | U33: 1.출원 | V33: PR20240352US | W33: 현실세계와 가상세계 간 연동을 위한 디지털 트윈 | X33: 1.한국 | Y33: 김용운
A34: ICT전략연구소 | B34: 표준연구본부 | C34: 33 | D34: Internet of Things (IoT) - Functional requirements to determine the status of squarantine through Internet of Things data interfaces | E34: ISO/IEC DTS 30180 | F34: ISO/IEC JTC1 | G34: SC41 WG5 | H34: 개발중 | I34: 감염병 발생에 따른 긴급 보건위기 상황에서 격리자를 대상으로 격리 상태에 대한 원격 모니터링과 이상 상태 탐지를 위한 기능 구조와 요구사항을 정의 | J34: 2022 | K34: 2025 | L34: 김용운, 유상근, 김성혜, 이창규 | M34: 에디터(김용운) | O34: 표준개발과제(국표원 표준기술력향상사업) | P34: 산업부 | Q34: 12) ICT융합 | R34: 안전ICT융합 | S34: 무 | T34: 0
A35: ICT전략연구소 | B35: 표준연구본부 | C35: 34 | D35: Reference model of integrating virtual and physical worlds through digital twins for the metaverse | E35: ITU-T Y.dtmv-ref | F35: ITU-T | G35: SG20 Q1 | H35: 개발중 | I35: 디지털 트윈 기반의 현실 가상 통합을 통해 메타버스 서비스로서 제공할 때 기능 참조구조 및 기능 구성요소를 정의 | J35: 2024 | K35: 2025 | L35: 김학서 | M35: 에디터(김학서) | N35: SG20 Q1 라포처(이준섭) SG20 의장(김형준) | O35: 표준개발과제(과기부 정보통신방송표준개발지원사업) | P35: 과기부 | Q35: 10) 메타버스 | R35: 초실감 상호작용 기술 | S35: 유 | T35: 1 | U35: 1.출원 | V35: PR20230929US | W35: 현실세계와 가상세계 간 연동을 위한 디지털 트윈 | X35: 1.한국 | Y35: 김학서
A36: ICT전략연구소 | B36: 표준연구본부 | C36: 35 | D36: General overview of IPv6-based NGN | E36: ITU-T Y.2051 | F36: ITU-T | G36: SG13 Q9 | H36: 제정완료 | I36: NGN 환경에서의 IPv6 적용모델 제시 | J36: 2006 | K36: 2008 | L36: 박정수 | O36: 표준개발과제(과기부 정보통신방송표준개발지원사업) | P36: 과기부 | Q36: 12) ICT융합 | R36: 기타 | S36: 무 | T36: 0
A37: ICT전략연구소 | B37: 표준연구본부 | C37: 36 | D37: Requirements of water quality assessment services in ubiquitous sensor network (USN) | E37: ITU-T F.747.6 | F37: ITU-T | G37: SG16 Q25 | H37: 제정완료 | I37: 국내 하천을 기반으로 원격 수질관리 모델을 제시 (ETRI 기술개발 과제와의 연계표준) | J37: 2012 | K37: 2016 | L37: 박정수 | O37: 표준개발과제(과기부 정보통신방송표준개발지원사업) | P37: 과기부 | Q37: 12) ICT융합 | R37: 산업ICT융합 | S37: 무 | T37: 0
A38: ICT전략연구소 | B38: 표준연구본부 | C38: 37 | D38: Security services using software-defined networking | E38: ITU-T X.1042 | F38: ITU-T | G38: SG17 Q6 | H38: 제정완료 | I38: 소프트웨어 정의 네트워킹(SDN) 환경에서의 보안 요구사항 제시 (IETF I2NSFWG 문제정의 RFC와의 연계 표준) | J38: 2014 | K38: 2019 | L38: 박정수 | O38: 표준개발과제(과기부 정보통신방송표준개발지원사업) | P38: 과기부 | Q38: 5) 사이버보안 | R38: 네트워크 클라우드 보안 | S38: 무 | T38: 0
A39: ICT전략연구소 | B39: 표준연구본부 | C39: 38 | D39: Security framework and requirements for service function chaining based on software-defined networking | E39: ITU-T X.1043 | F39: ITU-T | G39: SG17 Q2 | H39: 제정완료 | I39: 소프트웨어 정의 네트워킹(SDN) 환경에서의 서비스 함수 체이닝(SFC) 보안 프레임워크 제시 | J39: 2017 | K39: 2019 | L39: 박정수 | O39: 표준개발과제(과기부 정보통신방송표준개발지원사업) | P39: 과기부 | Q39: 5) 사이버보안 | R39: 네트워크 클라우드 보안 | S39: 무 | T39: 0
A40: ICT전략연구소 | B40: 표준연구본부 | C40: 39 | D40: Blockchain-based data exchange and sharing for supporting Internet of things and smart cities and communities | E40: ITU-T Y.4560 | F40: ITU-T | G40: SG20 Q4 | H40: 제정완료 | I40: 디지털 자산의 공유 및 교환 요구사항 및 유즈케이스 제시 | J40: 2019 | K40: 2020 | L40: 박정수 | M40: 에디터(박정수) | N40: SG20 의장(김형준) | O40: 표준개발과제(과기부 정보통신방송표준개발지원사업) | P40: 과기부 | Q40: 5) 사이버보안 | R40: 데이터 및 AI보안 | S40: 무 | T40: 0 | AA40: R
...

Sheet 결과
E1: 응답건수 | G1: N | H1: R | J1: 2025년도
B2: 직할부서 | E2: 2024년도 | F2: 2025년도 | G2: 신규추가 | H2: 갱신건수 | J2: 계획중 | K2: 제안중 | L2: 개발중 | M2: 제정완료 | N2: 개발중단 | O2: 추진건수
B4: 인공지능컴퓨팅연구소 | C4: 사이버보안연구본부 | F4: =COUNTIF(취합!$B:$B,결과!C4) -> 57 | G4: =IF(COUNTIFS(취합!$B:$B,결과!C4,취합!$AA:$AA,G$1)=0,"",COUNTIFS(취합!$B:$B,결과!C4,취합!$AA:$AA,G$1)) | H4: =IF(COUNTIFS(취합!$B:$B,결과!C4, 취합!$AA:$AA,H$1)=0,"",COUNTIFS(취합!$B:$B,결과!C4, 취합!$AA:$AA,H$1)) | J4: =IF(COUNTIFS(취합!$B:$B,결과!$C4,취합!$H:$H,"계획중")=0,"",COUNTIFS(취합!$B:$B,결과!$C4,취합!$H:$H,"계획중")) | K4: =IF(COUNTIFS(취합!$B:$B,결과!$C4,취합!$H:$H,"제안중")=0,"",COUNTIFS(취합!$B:$B,결과!$C4,취합!$H:$H,"제안중")) | L4: =IF(COUNTIFS(취합!$B:$B,결과!$C4,취합!$H:$H,"개발중")=0,"",COUNTIFS(취합!$B:$B,결과!$C4,취합!$H:$H,"개발중")) -> 14 | M4: =IF(COUNTIFS(취합!$B:$B,결과!$C4,취합!$H:$H,"제정완료")=0,"",COUNTIFS(취합!$B:$B,결과!$C4,취합!$H:$H,"제정완료")) -> 42 | N4: =IF(COUNTIFS(취합!$B:$B,결과!$C4,취합!$H:$H,"개발중단")=0,"",COUNTIFS(취합!$B:$B,결과!$C4,취합!$H:$H,"개발중단")) -> 1 | O4: =IF(N4="", SUM(J4:M4), SUM(J4:M4)) -> 56
B5: 인공지능컴퓨팅연구소 | C5: 온디바이스AI연구본부 | F5: =COUNTIF(취합!$B:$B,결과!C5) -> 1 | G5: =IF(COUNTIFS(취합!$B:$B,결과!C5,취합!$AA:$AA,G$1)=0,"",COUNTIFS(취합!$B:$B,결과!C5,취합!$AA:$AA,G$1)) | H5: =IF(COUNTIFS(취합!$B:$B,결과!C5, 취합!$AA:$AA,H$1)=0,"",COUNTIFS(취합!$B:$B,결과!C5, 취합!$AA:$AA,H$1)) | J5: =IF(COUNTIFS(취합!$B:$B,결과!$C5,취합!$H:$H,"계획중")=0,"",COUNTIFS(취합!$B:$B,결과!$C5,취합!$H:$H,"계획중")) | K5: =IF(COUNTIFS(취합!$B:$B,결과!$C5,취합!$H:$H,"제안중")=0,"",COUNTIFS(취합!$B:$B,결과!$C5,취합!$H:$H,"제안중")) | L5: =IF(COUNTIFS(취합!$B:$B,결과!$C5,취합!$H:$H,"개발중")=0,"",COUNTIFS(취합!$B:$B,결과!$C5,취합!$H:$H,"개발중")) -> 1 | M5: =IF(COUNTIFS(취합!$B:$B,결과!$C5,취합!$H:$H,"제정완료")=0,"",COUNTIFS(취합!$B:$B,결과!$C5,취합!$H:$H,"제정완료")) | N5: =IF(COUNTIFS(취합!$B:$B,결과!$C5,취합!$H:$H,"개발중단")=0,"",COUNTIFS(취합!$B:$B,결과!$C5,취합!$H:$H,"개발중단")) | O5: =IF(N5="", SUM(J5:M5), SUM(J5:M5)) -> 1
B6: 인공지능컴퓨팅연구소 | C6: 초성능컴퓨팅연구본부 | F6: =COUNTIF(취합!$B:$B,결과!C6) -> 24 | G6: =IF(COUNTIFS(취합!$B:$B,결과!C6,취합!$AA:$AA,G$1)=0,"",COUNTIFS(취합!$B:$B,결과!C6,취합!$AA:$AA,G$1)) | H6: =IF(COUNTIFS(취합!$B:$B,결과!C6, 취합!$AA:$AA,H$1)=0,"",COUNTIFS(취합!$B:$B,결과!C6, 취합!$AA:$AA,H$1)) -> 4 | J6: =IF(COUNTIFS(취합!$B:$B,결과!$C6,취합!$H:$H,"계획중")=0,"",COUNTIFS(취합!$B:$B,결과!$C6,취합!$H:$H,"계획중")) -> 6 | K6: =IF(COUNTIFS(취합!$B:$B,결과!$C6,취합!$H:$H,"제안중")=0,"",COUNTIFS(취합!$B:$B,결과!$C6,취합!$H:$H,"제안중")) | L6: =IF(COUNTIFS(취합!$B:$B,결과!$C6,취합!$H:$H,"개발중")=0,"",COUNTIFS(취합!$B:$B,결과!$C6,취합!$H:$H,"개발중")) -> 7 | M6: =IF(COUNTIFS(취합!$B:$B,결과!$C6,취합!$H:$H,"제정완료")=0,"",COUNTIFS(취합!$B:$B,결과!$C6,취합!$H:$H,"제정완료")) -> 11 | N6: =IF(COUNTIFS(취합!$B:$B,결과!$C6,취합!$H:$H,"개발중단")=0,"",COUNTIFS(취합!$B:$B,결과!$C6,취합!$H:$H,"개발중단")) | O6: =IF(N6="", SUM(J6:M6), SUM(J6:M6)) -> 24
B7: 소계 | E7: 75 | F7: =SUM(F4:F6) -> 82 | G7: =SUM(G4:G6) -> 0 | H7: =SUM(H4:H6) -> 4 | J7: =SUM(J4:J6) -> 6 | K7: =SUM(K4:K6) -> 0 | L7: =SUM(L4:L6) -> 22 | M7: =SUM(M4:M6) -> 53 | N7: =SUM(N4:N6) -> 1 | O7: =IF(N7="", SUM(J7:M7), SUM(J7:M7)) -> 81
B9: 초지능창의연구소 | C9: 모빌리티로봇연구본부 | F9: =COUNTIF(취합!$B:$B,결과!C9) -> 6 | G9: =IF(COUNTIFS(취합!$B:$B,결과!C9,취합!$AA:$AA,G$1)=0,"",COUNTIFS(취합!$B:$B,결과!C9,취합!$AA:$AA,G$1)) -> 6 | H9: =IF(COUNTIFS(취합!$B:$B,결과!C9, 취합!$AA:$AA,H$1)=0,"",COUNTIFS(취합!$B:$B,결과!C9, 취합!$AA:$AA,H$1)) | J9: =IF(COUNTIFS(취합!$B:$B,결과!$C9,취합!$H:$H,"계획중")=0,"",COUNTIFS(취합!$B:$B,결과!$C9,취합!$H:$H,"계획중")) | K9: =IF(COUNTIFS(취합!$B:$B,결과!$C9,취합!$H:$H,"제안중")=0,"",COUNTIFS(취합!$B:$B,결과!$C9,취합!$H:$H,"제안중")) | L9: =IF(COUNTIFS(취합!$B:$B,결과!$C9,취합!$H:$H,"개발중")=0,"",COUNTIFS(취합!$B:$B,결과!$C9,취합!$H:$H,"개발중")) -> 2 | M9: =IF(COUNTIFS(취합!$B:$B,결과!$C9,취합!$H:$H,"제정완료")=0,"",COUNTIFS(취합!$B:$B,결과!$C9,취합!$H:$H,"제정완료")) -> 4 | N9: =IF(COUNTIFS(취합!$B:$B,결과!$C9,취합!$H:$H,"개발중단")=0,"",COUNTIFS(취합!$B:$B,결과!$C9,취합!$H:$H,"개발중단")) | O9: =IF(N9="", SUM(J9:M9), SUM(J9:M9)) -> 6
B10: 초지능창의연구소 | C10: 지능정보연구본부 | F10: =COUNTIF(취합!$B:$B,결과!C10) -> 5 | G10: =IF(COUNTIFS(취합!$B:$B,결과!C10,취합!$AA:$AA,G$1)=0,"",COUNTIFS(취합!$B:$B,결과!C10,취합!$AA:$AA,G$1)) -> 2 | H10: =IF(COUNTIFS(취합!$B:$B,결과!C10, 취합!$AA:$AA,H$1)=0,"",COUNTIFS(취합!$B:$B,결과!C10, 취합!$AA:$AA,H$1)) -> 1 | J10: =IF(COUNTIFS(취합!$B:$B,결과!$C10,취합!$H:$H,"계획중")=0,"",COUNTIFS(취합!$B:$B,결과!$C10,취합!$H:$H,"계획중")) | K10: =IF(COUNTIFS(취합!$B:$B,결과!$C10,취합!$H:$H,"제안중")=0,"",COUNTIFS(취합!$B:$B,결과!$C10,취합!$H:$H,"제안중")) | L10: =IF(COUNTIFS(취합!$B:$B,결과!$C10,취합!$H:$H,"개발중")=0,"",COUNTIFS(취합!$B:$B,결과!$C10,취합!$H:$H,"개발중")) -> 1 | M10: =IF(COUNTIFS(취합!$B:$B,결과!$C10,취합!$H:$H,"제정완료")=0,"",COUNTIFS(취합!$B:$B,결과!$C10,취합!$H:$H,"제정완료")) -> 4 | N10: =IF(COUNTIFS(취합!$B:$B,결과!$C10,취합!$H:$H,"개발중단")=0,"",COUNTIFS(취합!$B:$B,결과!$C10,취합!$H:$H,"개발중단")) | O10: =IF(N10="", SUM(J10:M10), SUM(J10:M10)) -> 5
B11: 초지능창의연구소 | C11: 창의원천연구본부 | F11: =COUNTIF(취합!$B:$B,결과!C11) -> 4 | G11: =IF(COUNTIFS(취합!$B:$B,결과!C11,취합!$AA:$AA,G$1)=0,"",COUNTIFS(취합!$B:$B,결과!C11,취합!$AA:$AA,G$1)) -> 2 | H11: =IF(COUNTIFS(취합!$B:$B,결과!C11, 취합!$AA:$AA,H$1)=0,"",COUNTIFS(취합!$B:$B,결과!C11, 취합!$AA:$AA,H$1)) | J11: =IF(COUNTIFS(취합!$B:$B,결과!$C11,취합!$H:$H,"계획중")=0,"",COUNTIFS(취합!$B:$B,결과!$C11,취합!$H:$H,"계획중")) | K11: =IF(COUNTIFS(취합!$B:$B,결과!$C11,취합!$H:$H,"제안중")=0,"",COUNTIFS(취합!$B:$B,결과!$C11,취합!$H:$H,"제안중")) -> 2 | L11: =IF(COUNTIFS(취합!$B:$B,결과!$C11,취합!$H:$H,"개발중")=0,"",COUNTIFS(취합!$B:$B,결과!$C11,취합!$H:$H,"개발중")) -> 2 | M11: =IF(COUNTIFS(취합!$B:$B,결과!$C11,취합!$H:$H,"제정완료")=0,"",COUNTIFS(취합!$B:$B,결과!$C11,취합!$H:$H,"제정완료")) | N11: =IF(COUNTIFS(취합!$B:$B,결과!$C11,취합!$H:$H,"개발중단")=0,"",COUNTIFS(취합!$B:$B,결과!$C11,취합!$H:$H,"개발중단")) | O11: =IF(N11="", SUM(J11:M11), SUM(J11:M11)) -> 4
B12: 소계 | E12: 15 | F12: =SUM(F9:F11) -> 15 | G12: =SUM(G9:G11) -> 10 | H12: =SUM(H9:H11) -> 1 | J12: =SUM(J9:J11) -> 0 | K12: =SUM(K9:K11) -> 2 | L12: =SUM(L9:L11) -> 5 | M12: =SUM(M9:M11) -> 8 | N12: =SUM(N9:N11) -> 0 | O12: =IF(N12="", SUM(J12:M12), SUM(J12:M12)) -> 15
B14: 입체통신연구소 | C14: 네트워크연구본부 | F14: =COUNTIF(취합!$B:$B,결과!C14) -> 65 | G14: =IF(COUNTIFS(취합!$B:$B,결과!C14,취합!$AA:$AA,G$1)=0,"",COUNTIFS(취합!$B:$B,결과!C14,취합!$AA:$AA,G$1)) -> 4 | H14: =IF(COUNTIFS(취합!$B:$B,결과!C14, 취합!$AA:$AA,H$1)=0,"",COUNTIFS(취합!$B:$B,결과!C14, 취합!$AA:$AA,H$1)) -> 13 | J14: =IF(COUNTIFS(취합!$B:$B,결과!$C14,취합!$H:$H,"계획중")=0,"",COUNTIFS(취합!$B:$B,결과!$C14,취합!$H:$H,"계획중")) -> 1 | K14: =IF(COUNTIFS(취합!$B:$B,결과!$C14,취합!$H:$H,"제안중")=0,"",COUNTIFS(취합!$B:$B,결과!$C14,취합!$H:$H,"제안중")) -> 4 | L14: =IF(COUNTIFS(취합!$B:$B,결과!$C14,취합!$H:$H,"개발중")=0,"",COUNTIFS(취합!$B:$B,결과!$C14,취합!$H:$H,"개발중")) -> 18 | M14: =IF(COUNTIFS(취합!$B:$B,결과!$C14,취합!$H:$H,"제정완료")=0,"",COUNTIFS(취합!$B:$B,결과!$C14,취합!$H:$H,"제정완료")) -> 41 | N14: =IF(COUNTIFS(취합!$B:$B,결과!$C14,취합!$H:$H,"개발중단")=0,"",COUNTIFS(취합!$B:$B,결과!$C14,취합!$H:$H,"개발중단")) -> 1 | O14: =IF(N14="", SUM(J14:M14), SUM(J14:M14)) -> 64
B15: 입체통신연구소 | C15: 위성통신연구본부 | F15: =COUNTIF(취합!$B:$B,결과!C15) -> 35 | G15: =IF(COUNTIFS(취합!$B:$B,결과!C15,취합!$AA:$AA,G$1)=0,"",COUNTIFS(취합!$B:$B,결과!C15,취합!$AA:$AA,G$1)) | H15: =IF(COUNTIFS(취합!$B:$B,결과!C15, 취합!$AA:$AA,H$1)=0,"",COUNTIFS(취합!$B:$B,결과!C15, 취합!$AA:$AA,H$1)) -> 5 | J15: =IF(COUNTIFS(취합!$B:$B,결과!$C15,취합!$H:$H,"계획중")=0,"",COUNTIFS(취합!$B:$B,결과!$C15,취합!$H:$H,"계획중")) -> 2 | K15: =IF(COUNTIFS(취합!$B:$B,결과!$C15,취합!$H:$H,"제안중")=0,"",COUNTIFS(취합!$B:$B,결과!$C15,취합!$H:$H,"제안중")) -> 7 | L15: =IF(COUNTIFS(취합!$B:$B,결과!$C15,취합!$H:$H,"개발중")=0,"",COUNTIFS(취합!$B:$B,결과!$C15,취합!$H:$H,"개발중")) -> 14 | M15: =IF(COUNTIFS(취합!$B:$B,결과!$C15,취합!$H:$H,"제정완료")=0,"",COUNTIFS(취합!$B:$B,결과!$C15,취합!$H:$H,"제정완료")) -> 12 | N15: =IF(COUNTIFS(취합!$B:$B,결과!$C15,취합!$H:$H,"개발중단")=0,"",COUNTIFS(취합!$B:$B,결과!$C15,취합!$H:$H,"개발중단")) | O15: =IF(N15="", SUM(J15:M15), SUM(J15:M15)) -> 35
B16: 입체통신연구소 | C16: 이동통신연구본부 | F16: =COUNTIF(취합!$B:$B,결과!C16) -> 29 | G16: =IF(COUNTIFS(취합!$B:$B,결과!C16,취합!$AA:$AA,G$1)=0,"",COUNTIFS(취합!$B:$B,결과!C16,취합!$AA:$AA,G$1)) -> 7 | H16: =IF(COUNTIFS(취합!$B:$B,결과!C16, 취합!$AA:$AA,H$1)=0,"",COUNTIFS(취합!$B:$B,결과!C16, 취합!$AA:$AA,H$1)) -> 8 | J16: =IF(COUNTIFS(취합!$B:$B,결과!$C16,취합!$H:$H,"계획중")=0,"",COUNTIFS(취합!$B:$B,결과!$C16,취합!$H:$H,"계획중")) -> 7 | K16: =IF(COUNTIFS(취합!$B:$B,결과!$C16,취합!$H:$H,"제안중")=0,"",COUNTIFS(취합!$B:$B,결과!$C16,취합!$H:$H,"제안중")) -> 1 | L16: =IF(COUNTIFS(취합!$B:$B,결과!$C16,취합!$H:$H,"개발중")=0,"",COUNTIFS(취합!$B:$B,결과!$C16,취합!$H:$H,"개발중")) -> 20 | M16: =IF(COUNTIFS(취합!$B:$B,결과!$C16,취합!$H:$H,"제정완료")=0,"",COUNTIFS(취합!$B:$B,결과!$C16,취합!$H:$H,"제정완료")) -> 1 | N16: =IF(COUNTIFS(취합!$B:$B,결과!$C16,취합!$H:$H,"개발중단")=0,"",COUNTIFS(취합!$B:$B,결과!$C16,취합!$H:$H,"개발중단")) | O16: =IF(N16="", SUM(J16:M16), SUM(J16:M16)) -> 29
B17: 입체통신연구소 | C17: 전파연구본부 | F17: =COUNTIF(취합!$B:$B,결과!C17) -> 21 | G17: =IF(COUNTIFS(취합!$B:$B,결과!C17,취합!$AA:$AA,G$1)=0,"",COUNTIFS(취합!$B:$B,결과!C17,취합!$AA:$AA,G$1)) | H17: =IF(COUNTIFS(취합!$B:$B,결과!C17, 취합!$AA:$AA,H$1)=0,"",COUNTIFS(취합!$B:$B,결과!C17, 취합!$AA:$AA,H$1)) -> 3 | J17: =IF(COUNTIFS(취합!$B:$B,결과!$C17,취합!$H:$H,"계획중")=0,"",COUNTIFS(취합!$B:$B,결과!$C17,취합!$H:$H,"계획중")) | K17: =IF(COUNTIFS(취합!$B:$B,결과!$C17,취합!$H:$H,"제안중")=0,"",COUNTIFS(취합!$B:$B,결과!$C17,취합!$H:$H,"제안중")) | L17: =IF(COUNTIFS(취합!$B:$B,결과!$C17,취합!$H:$H,"개발중")=0,"",COUNTIFS(취합!$B:$B,결과!$C17,취합!$H:$H,"개발중")) -> 8 | M17: =IF(COUNTIFS(취합!$B:$B,결과!$C17,취합!$H:$H,"제정완료")=0,"",COUNTIFS(취합!$B:$B,결과!$C17,취합!$H:$H,"제정완료")) -> 13 | N17: =IF(COUNTIFS(취합!$B:$B,결과!$C17,취합!$H:$H,"개발중단")=0,"",COUNTIFS(취합!$B:$B,결과!$C17,취합!$H:$H,"개발중단")) | O17: =IF(N17="", SUM(J17:M17), SUM(J17:M17)) -> 21
B18: 소계 | E18: 134 | F18: =SUM(F14:F17) -> 150 | G18: =SUM(G14:G17) -> 11 | H18: =SUM(H14:H17) -> 29 | J18: =SUM(J14:J17) -> 10 | K18: =SUM(K14:K17) -> 12 | L18: =SUM(L14:L17) -> 60 | M18: =SUM(M14:M17) -> 67 | N18: =SUM(N14:N17) -> 1 | O18: =IF(N18="", SUM(J18:M18), SUM(J18:M18)) -> 149
B20: 초실감메타버스연구소 | C20: 미디어연구본부 | F20: =COUNTIF(취합!$B:$B,결과!C20) -> 35 | G20: =IF(COUNTIFS(취합!$B:$B,결과!C20,취합!$AA:$AA,G$1)=0,"",COUNTIFS(취합!$B:$B,결과!C20,취합!$AA:$AA,G$1)) -> 9 | H20: =IF(COUNTIFS(취합!$B:$B,결과!C20, 취합!$AA:$AA,H$1)=0,"",COUNTIFS(취합!$B:$B,결과!C20, 취합!$AA:$AA,H$1)) -> 2 | J20: =IF(COUNTIFS(취합!$B:$B,결과!$C20,취합!$H:$H,"계획중")=0,"",COUNTIFS(취합!$B:$B,결과!$C20,취합!$H:$H,"계획중")) -> 4 | K20: =IF(COUNTIFS(취합!$B:$B,결과!$C20,취합!$H:$H,"제안중")=0,"",COUNTIFS(취합!$B:$B,결과!$C20,취합!$H:$H,"제안중")) | L20: =IF(COUNTIFS(취합!$B:$B,결과!$C20,취합!$H:$H,"개발중")=0,"",COUNTIFS(취합!$B:$B,결과!$C20,취합!$H:$H,"개발중")) -> 19 | M20: =IF(COUNTIFS(취합!$B:$B,결과!$C20,취합!$H:$H,"제정완료")=0,"",COUNTIFS(취합!$B:$B,결과!$C20,취합!$H:$H,"제정완료")) -> 12 | N20: =IF(COUNTIFS(취합!$B:$B,결과!$C20,취합!$H:$H,"개발중단")=0,"",COUNTIFS(취합!$B:$B,결과!$C20,취합!$H:$H,"개발중단")) | O20: =IF(N20="", SUM(J20:M20), SUM(J20:M20)) -> 35
B21: 초실감메타버스연구소 | C21: 실감소자연구본부 | F21: =COUNTIF(취합!$B:$B,결과!C21) -> 12 | G21: =IF(COUNTIFS(취합!$B:$B,결과!C21,취합!$AA:$AA,G$1)=0,"",COUNTIFS(취합!$B:$B,결과!C21,취합!$AA:$AA,G$1)) -> 5 | H21: =IF(COUNTIFS(취합!$B:$B,결과!C21, 취합!$AA:$AA,H$1)=0,"",COUNTIFS(취합!$B:$B,결과!C21, 취합!$AA:$AA,H$1)) -> 4 | J21: =IF(COUNTIFS(취합!$B:$B,결과!$C21,취합!$H:$H,"계획중")=0,"",COUNTIFS(취합!$B:$B,결과!$C21,취합!$H:$H,"계획중")) | K21: =IF(COUNTIFS(취합!$B:$B,결과!$C21,취합!$H:$H,"제안중")=0,"",COUNTIFS(취합!$B:$B,결과!$C21,취합!$H:$H,"제안중")) -> 1 | L21: =IF(COUNTIFS(취합!$B:$B,결과!$C21,취합!$H:$H,"개발중")=0,"",COUNTIFS(취합!$B:$B,결과!$C21,취합!$H:$H,"개발중")) -> 3 | M21: =IF(COUNTIFS(취합!$B:$B,결과!$C21,취합!$H:$H,"제정완료")=0,"",COUNTIFS(취합!$B:$B,결과!$C21,취합!$H:$H,"제정완료")) -> 8 | N21: =IF(COUNTIFS(취합!$B:$B,결과!$C21,취합!$H:$H,"개발중단")=0,"",COUNTIFS(취합!$B:$B,결과!$C21,취합!$H:$H,"개발중단")) | O21: =IF(N21="", SUM(J21:M21), SUM(J21:M21)) -> 12
B22: 초실감메타버스연구소 | C22: 콘텐츠연구본부 | F22: =COUNTIF(취합!$B:$B,결과!C22) -> 12 | G22: =IF(COUNTIFS(취합!$B:$B,결과!C22,취합!$AA:$AA,G$1)=0,"",COUNTIFS(취합!$B:$B,결과!C22,취합!$AA:$AA,G$1)) -> 8 | H22: =IF(COUNTIFS(취합!$B:$B,결과!C22, 취합!$AA:$AA,H$1)=0,"",COUNTIFS(취합!$B:$B,결과!C22, 취합!$AA:$AA,H$1)) | J22: =IF(COUNTIFS(취합!$B:$B,결과!$C22,취합!$H:$H,"계획중")=0,"",COUNTIFS(취합!$B:$B,결과!$C22,취합!$H:$H,"계획중")) -> 3 | K22: =IF(COUNTIFS(취합!$B:$B,결과!$C22,취합!$H:$H,"제안중")=0,"",COUNTIFS(취합!$B:$B,결과!$C22,취합!$H:$H,"제안중")) | L22: =IF(COUNTIFS(취합!$B:$B,결과!$C22,취합!$H:$H,"개발중")=0,"",COUNTIFS(취합!$B:$B,결과!$C22,취합!$H:$H,"개발중")) -> 5 | M22: =IF(COUNTIFS(취합!$B:$B,결과!$C22,취합!$H:$H,"제정완료")=0,"",COUNTIFS(취합!$B:$B,결과!$C22,취합!$H:$H,"제정완료")) -> 4 | N22: =IF(COUNTIFS(취합!$B:$B,결과!$C22,취합!$H:$H,"개발중단")=0,"",COUNTIFS(취합!$B:$B,결과!$C22,취합!$H:$H,"개발중단")) | O22: =IF(N22="", SUM(J22:M22), SUM(J22:M22)) -> 12
B23: 소계 | E23: 57 | F23: =SUM(F20:F22) -> 59 | G23: =SUM(G20:G22) -> 22 | H23: =SUM(H20:H22) -> 6 | J23: =SUM(J20:J22) -> 7 | K23: =SUM(K20:K22) -> 1 | L23: =SUM(L20:L22) -> 27 | M23: =SUM(M20:M22) -> 24 | N23: =SUM(N20:N22) -> 0 | O23: =IF(N23="", SUM(J23:M23), SUM(J23:M23)) -> 59
B25: 디지털융합연구소 | C25: 산업에너지융합연구본부 | F25: =COUNTIF(취합!$B:$B,결과!C25) -> 20 | G25: =IF(COUNTIFS(취합!$B:$B,결과!C25,취합!$AA:$AA,G$1)=0,"",COUNTIFS(취합!$B:$B,결과!C25,취합!$AA:$AA,G$1)) | H25: =IF(COUNTIFS(취합!$B:$B,결과!C25, 취합!$AA:$AA,H$1)=0,"",COUNTIFS(취합!$B:$B,결과!C25, 취합!$AA:$AA,H$1)) -> 6 | J25: =IF(COUNTIFS(취합!$B:$B,결과!$C25,취합!$H:$H,"계획중")=0,"",COUNTIFS(취합!$B:$B,결과!$C25,취합!$H:$H,"계획중")) | K25: =IF(COUNTIFS(취합!$B:$B,결과!$C25,취합!$H:$H,"제안중")=0,"",COUNTIFS(취합!$B:$B,결과!$C25,취합!$H:$H,"제안중")) | L25: =IF(COUNTIFS(취합!$B:$B,결과!$C25,취합!$H:$H,"개발중")=0,"",COUNTIFS(취합!$B:$B,결과!$C25,취합!$H:$H,"개발중")) -> 2 | M25: =IF(COUNTIFS(취합!$B:$B,결과!$C25,취합!$H:$H,"제정완료")=0,"",COUNTIFS(취합!$B:$B,결과!$C25,취합!$H:$H,"제정완료")) -> 18 | N25: =IF(COUNTIFS(취합!$B:$B,결과!$C25,취합!$H:$H,"개발중단")=0,"",COUNTIFS(취합!$B:$B,결과!$C25,취합!$H:$H,"개발중단")) | O25: =IF(N25="", SUM(J25:M25), SUM(J25:M25)) -> 20
B26: 디지털융합연구소 | C26: 에어모빌리티연구본부 | F26: =COUNTIF(취합!$B:$B,결과!C26) -> 8 | G26: =IF(COUNTIFS(취합!$B:$B,결과!C26,취합!$AA:$AA,G$1)=0,"",COUNTIFS(취합!$B:$B,결과!C26,취합!$AA:$AA,G$1)) | H26: =IF(COUNTIFS(취합!$B:$B,결과!C26, 취합!$AA:$AA,H$1)=0,"",COUNTIFS(취합!$B:$B,결과!C26, 취합!$AA:$AA,H$1)) -> 1 | J26: =IF(COUNTIFS(취합!$B:$B,결과!$C26,취합!$H:$H,"계획중")=0,"",COUNTIFS(취합!$B:$B,결과!$C26,취합!$H:$H,"계획중")) | K26: =IF(COUNTIFS(취합!$B:$B,결과!$C26,취합!$H:$H,"제안중")=0,"",COUNTIFS(취합!$B:$B,결과!$C26,취합!$H:$H,"제안중")) | L26: =IF(COUNTIFS(취합!$B:$B,결과!$C26,취합!$H:$H,"개발중")=0,"",COUNTIFS(취합!$B:$B,결과!$C26,취합!$H:$H,"개발중")) -> 2 | M26: =IF(COUNTIFS(취합!$B:$B,결과!$C26,취합!$H:$H,"제정완료")=0,"",COUNTIFS(취합!$B:$B,결과!$C26,취합!$H:$H,"제정완료")) -> 6 | N26: =IF(COUNTIFS(취합!$B:$B,결과!$C26,취합!$H:$H,"개발중단")=0,"",COUNTIFS(취합!$B:$B,결과!$C26,취합!$H:$H,"개발중단")) | O26: =IF(N26="", SUM(J26:M26), SUM(J26:M26)) -> 8
B27: 소계 | E27: 25 | F27: =SUM(F25:F26) -> 28 | G27: =SUM(G25:G26) -> 0 | H27: =SUM(H25:H26) -> 7 | J27: =SUM(J25:J26) -> 0 | K27: =SUM(K25:K26) -> 0 | L27: =SUM(L25:L26) -> 4 | M27: =SUM(M25:M26) -> 24 | N27: =SUM(N25:N26) -> 0 | O27: =IF(N27="", SUM(J27:M27), SUM(J27:M27)) -> 28
B29: ICT전략연구소 | C29: 표준연구본부 | F29: =COUNTIF(취합!$B:$B,결과!C29) -> 313 | G29: =IF(COUNTIFS(취합!$B:$B,결과!C29,취합!$AA:$AA,G$1)=0,"",COUNTIFS(취합!$B:$B,결과!C29,취합!$AA:$AA,G$1)) -> 12 | H29: =IF(COUNTIFS(취합!$B:$B,결과!C29, 취합!$AA:$AA,H$1)=0,"",COUNTIFS(취합!$B:$B,결과!C29, 취합!$AA:$AA,H$1)) -> 37 | J29: =IF(COUNTIFS(취합!$B:$B,결과!$C29,취합!$H:$H,"계획중")=0,"",COUNTIFS(취합!$B:$B,결과!$C29,취합!$H:$H,"계획중")) -> 7 | K29: =IF(COUNTIFS(취합!$B:$B,결과!$C29,취합!$H:$H,"제안중")=0,"",COUNTIFS(취합!$B:$B,결과!$C29,취합!$H:$H,"제안중")) -> 9 | L29: =IF(COUNTIFS(취합!$B:$B,결과!$C29,취합!$H:$H,"개발중")=0,"",COUNTIFS(취합!$B:$B,결과!$C29,취합!$H:$H,"개발중")) -> 72 | M29: =IF(COUNTIFS(취합!$B:$B,결과!$C29,취합!$H:$H,"제정완료")=0,"",COUNTIFS(취합!$B:$B,결과!$C29,취합!$H:$H,"제정완료")) -> 223 | N29: =IF(COUNTIFS(취합!$B:$B,결과!$C29,취합!$H:$H,"개발중단")=0,"",COUNTIFS(취합!$B:$B,결과!$C29,취합!$H:$H,"개발중단")) -> 2 | O29: =IF(N29="", SUM(J29:M29), SUM(J29:M29)) -> 311
B30: 소계 | E30: 287 | F30: =SUM(F29) -> 313 | G30: =SUM(G29) -> 12 | H30: =SUM(H29) -> 37 | J30: =SUM(J29) -> 7 | K30: =SUM(K29) -> 9 | L30: =SUM(L29) -> 72 | M30: =SUM(M29) -> 223 | N30: =SUM(N29) -> 2 | O30: =IF(N30="", SUM(J30:M30), SUM(J30:M30)) -> 311
B32: AI안전연구소 | C32: AI안전평가실 | F32: =COUNTIF(취합!$B:$B,결과!C32) -> 3 | G32: =IF(COUNTIFS(취합!$B:$B,결과!C32,취합!$AA:$AA,G$1)=0,"",COUNTIFS(취합!$B:$B,결과!C32,취합!$AA:$AA,G$1)) -> 2 | H32: =IF(COUNTIFS(취합!$B:$B,결과!C32, 취합!$AA:$AA,H$1)=0,"",COUNTIFS(취합!$B:$B,결과!C32, 취합!$AA:$AA,H$1)) | J32: =IF(COUNTIFS(취합!$B:$B,결과!$C32,취합!$H:$H,"계획중")=0,"",COUNTIFS(취합!$B:$B,결과!$C32,취합!$H:$H,"계획중")) | K32: =IF(COUNTIFS(취합!$B:$B,결과!$C32,취합!$H:$H,"제안중")=0,"",COUNTIFS(취합!$B:$B,결과!$C32,취합!$H:$H,"제안중")) | L32: =IF(COUNTIFS(취합!$B:$B,결과!$C32,취합!$H:$H,"개발중")=0,"",COUNTIFS(취합!$B:$B,결과!$C32,취합!$H:$H,"개발중")) -> 3 | M32: =IF(COUNTIFS(취합!$B:$B,결과!$C32,취합!$H:$H,"제정완료")=0,"",COUNTIFS(취합!$B:$B,결과!$C32,취합!$H:$H,"제정완료")) | N32: =IF(COUNTIFS(취합!$B:$B,결과!$C32,취합!$H:$H,"개발중단")=0,"",COUNTIFS(취합!$B:$B,결과!$C32,취합!$H:$H,"개발중단")) | O32: =IF(N32="", SUM(J32:M32), SUM(J32:M32)) -> 3
B33: 소계 | F33: =SUM(F32) -> 3 | G33: =SUM(G32) -> 2 | H33: =SUM(H32) -> 0 | J33: =SUM(J32) -> 0 | K33: =SUM(K32) -> 0 | L33: =SUM(L32) -> 3 | M33: =SUM(M32) -> 0 | N33: =SUM(N32) -> 0 | O33: =IF(N33="", SUM(J33:M33), SUM(J33:M33)) -> 3
B35: 총계 | E35: =SUM(E12,E23,E18,E7,E27,E30,E33) -> 593 | F35: =SUM(F12,F23,F18,F7,F27,F30,F33) -> 650 | G35: =SUM(G12,G23,G18,G7,G27,G30,G33) -> 57 | H35: =SUM(H12,H23,H18,H7,H27,H30,H33) -> 84 | J35: =SUM(J12,J23,J18,J7,J27,J30,J33) -> 30 | K35: =SUM(K12,K23,K18,K7,K27,K30,K33) -> 24 | L35: =SUM(L12,L23,L18,L7,L27,L30,L33) -> 193 | M35: =SUM(M12,M23,M18,M7,M27,M30,M33) -> 399 | N35: =SUM(N12,N23,N18,N7,N27,N30,N33) -> 4 | O35: =SUM(O12,O23,O18,O7,O27,O30,O33) -> 646

Sheet 개수
C2: 개수
B3: 인공지능컴퓨팅연구소 | C3: =COUNTIF(취합!A:A, B3) -> 82
B4: 초지능창의연구소 | C4: =COUNTIF(취합!A:A, B4) -> 15
B5: 입체통신연구소 | C5: =COUNTIF(취합!A:A, B5) -> 150
B6: 초실감메타버스연구소 | C6: =COUNTIF(취합!A:A, B6) -> 59
B7: 디지털융합연구소 | C7: =COUNTIF(취합!A:A, B7) -> 28
B8: ICT전략연구소 | C8: =COUNTIF(취합!A:A, B8) -> 313
C9: =SUM(C3:C8) -> 647

Sheet (참고) ETRI 12대 전략기술 및 42개 세부기술
B2: 12대 전략기술 | E2: 42개 세부중점기술 | K2: 기술분류표
A3: 1 | B3: 1) 반도체·디스플레이 | D3: 1 | E3: 고성능·저전력 AI 반도체 | BG3: 기본사업
A4: 2 | B4: 2) 이차전지 | D4: 2 | E4: 반도체 첨단 패키징 | BG4: ETRI 출연금사업
A5: 3 | B5: 3) 첨단모빌리티 | D5: 3 | E5: 고집적·저항기반 메모리 | BG5: 일반 PBS 과제
A6: 4 | B6: 4) 첨단바이오 | D6: 4 | E6: 차세대 고성능 센서 | BG6: 표준개발과제(과기부 정보통신방송표준개발지원사업)
A7: 5 | B7: 5) 사이버보안 | D7: 5 | E7: 전력반도체 | BG7: 표준개발과제(국표원 표준기술력향상사업)
A8: 6 | B8: 6) 인공지능 | D8: 6 | E8: 무기발광 디스플레이 | BG8: 기타
A9: 7 | B9: 7) 차세대통신 | D9: 7 | E9: 반도체·디스플레이 소재·부품·장비
A10: 8 | B10: 8) 첨단로봇제조 | D10: 8 | E10: 프리폼 디스플레이 | BG10: 계획중
A11: 9 | B11: 9) 양자 | E11: 기타 | W11: 2015 | X11: 2020 | BG11: 제안중
A12: 10 | B12: 10) 메타버스 | D12: 9 | E12: 차세대 이차전지 소재·셀 | W12: 2016 | X12: 2021 | BG12: 개발중
A13: 11 | B13: 11) 초성능컴퓨팅 | D13: 10 | E13: 이차전지 모듈·시스템 | W13: 2017 | X13: 2022 | BG13: 제정완료
A14: 12 | B14: 12) ICT융합 | E14: 기타 | W14: 2018 | X14: 2023
D15: 11 | E15: 자율주행시스템 | W15: 2019 | X15: 2024
D16: 12 | E16: 도심항공교통(UAM) | W16: 2020 | X16: 2025
E17: 기타 | W17: 2021 | X17: 2026
D18: 13 | E18: 디지털헬스 데이터 분석·활용 | W18: 2022 | X18: 2027
E19: 기타 | W19: 2023 | X19: 2028
D20: 14 | E20: 네트워크 클라우드 보안 | W20: 2024 | X20: 2029
D21: 15 | E21: 데이터 및 AI보안 | W21: 2025 | X21: 2030
D22: 16 | E22: 디지털 취약점 분석대응 | W22: 2026 | X22: 2031
D23: 17 | E23: 신산업·가상융합 보안 | W23: 2027 | X23: 2032
E24: 기타 | W24: 2028 | X24: 2033
D25: 18 | E25: 효율적학습/AI인프라고도화 | W25: 2029 | X25: 2034
D26: 19 | E26: 첨단 AI모델링·의사결정 | X26: 2035
D27: 20 | E27: 산업 활용·혁신 AI
D28: 21 | E28: 안전·신뢰 AI
D29: 22 | E29: 휴먼증강
E30: 기타
D31: 23 | E31: 5G 고도화
D32: 24 | E32: 5G·6G 고효율 통신부품
D33: 25 | E33: 5G·6G 위성통신
D34: 26 | E34: 6G
D35: 27 | E35: 오픈랜
E36: 기타
D37: 28 | E37: 고난도 자율조작
D38: 29 | E38: 로봇 자율이동
D39: 30 | E39: 인간·로봇 상호작용
D40: 31 | E40: 가상제조
E41: 기타
...
